Workbook

Sheet PLANNING
A1: Semaine | B1: Matricule | C1: NOM | D1: PRENOM | E1: NOM COMPLET | F1: Date d'embauche | G1: Activité | H1: N de téléphone | I1: Ville | J1: POINT DE REPERE | K1: ZONES | L1: LUN. Entrée | M1: LUN. Sortie | N1: MAR. Entrée | O1: MAR. Sortie | P1: MER. Entrée | Q1: MER. Sortie | R1: JEU. Entrée | S1: JEU. Sortie | T1: VEN. Entrée | U1: VEN. Sortie | V1: SAM. Entrée | W1: SAM. Sortie | X1: DIM. Entrée | Y1: DIM. Sortie
A2: S28 | B2: 1278 | C2: LISSAOUI | D2: HIBA | E2: LISSAOUI HIBA | F2: 45895 | G2: Accessibilité | H2: 06 25 79 47 45 | I2: TEMARA | J2: LYCEE SCIENTIFIQUES | K2: ZONE 6 | L2: 08H | M2: 18H | N2: 08H | O2: 18H | P2: 08H | Q2: 18H | R2: 08H | S2: 18H | T2: 08H | U2: 17H | V2: OFF | W2: OFF | X2: OFF | Y2: OFF
A3: S28 | B3: 1265 | C3: RMAIDI | D3: IMAD | E3: RMAIDI IMAD | F3: 45895 | G3: Accessibilité | H3: 06 44 93 74 73 | I3: SALE | J3: MAROC TELECOM SALA AL JADIDA | K3: ZONE 5 | L3: 08H | M3: 18H | N3: 08H | O3: 18H | P3: 08H | Q3: 18H | R3: 08H | S3: 18H | T3: 08H | U3: 17H | V3: OFF | W3: OFF | X3: OFF | Y3: OFF
A4: S28 | B4: 1317 | C4: HAMDANI | D4: MOHAMED | E4: HAMDANI MOHAMED | F4: 45903 | G4: Accessibilité | H4: 06 34 11 13 97 | I4: SALE | J4: BAB CHAAFA SALE | K4: ZONE 4 | L4: 08H | M4: 18H | N4: 08H | O4: 18H | P4: 08H | Q4: 18H | R4: 08H | S4: 18H | T4: 08H | U4: 17H | V4: OFF | W4: OFF | X4: OFF | Y4: OFF
A5: S28 | B5: 355 | C5: OUBRAHIM | D5: MOHAMMED | E5: OUBRAHIM MOHAMMED | F5: 44228 | G5: Accessibilité | H5: 06 95 49 92 98 | I5: KENITRA | J5: Parking Hôtel Relax | K5: ZONE 7 | L5: 08H | M5: 17H | N5: 08H | O5: 17H | P5: 08H | Q5: 17H | R5: 08H | S5: 17H | T5: 08H | U5: 17H | V5: OFF | W5: OFF | X5: OFF | Y5: OFF
A6: S28 | C6: EL MACHICHI | D6: SOUKAINA | E6: EL MACHICHI SOUKAINA | F6: 46174 | G6: Administration | H6: 07 67 58 52 11 | I6: SALE | J6: MARJANE HAY KARIMA | K6: ZONE 3 | L6: 09H | M6: 18H | N6: 09H | O6: 18H | P6: 09H | Q6: 18H | R6: 09H | S6: 18H | T6: 09H | U6: 18H | V6: OFF | W6: OFF | X6: OFF | Y6: OFF
A7: S28 | B7: 164 | C7: HMIDOUCH | D7: FOUAD | E7: HMIDOUCH FOUAD | F7: 44891 | G7: AFEDIM | H7: 06 74 23 90 72 | I7: KENITRA | J7: MOSQUEE CHAABI | K7: ZONE 7 | L7: 08H | M7: 17H | N7: 08H | O7: 17H | P7: 08H | Q7: 17H | R7: 08H | S7: 17H | T7: 08H | U7: 17H | V7: OFF | W7: OFF | X7: OFF | Y7: OFF
A8: S28 | B8: 777 | C8: RADGUI | D8: SARA | E8: RADGUI SARA | F8: 44809 | G8: AFEDIM | H8: 06 81 14 84 05 | I8: SALE | J8: ROND POINT HALIMA ROUTE DE KENITRA | K8: ZONE 4 | L8: 08H | M8: 18H | N8: 08H | O8: 18H | P8: 08H | Q8: 18H | R8: 08H | S8: 18H | T8: 08H | U8: 17H | V8: OFF | W8: OFF | X8: OFF | Y8: OFF
A9: S28 | B9: 973 | C9: BOUMEZGANE | D9: SOUKAINA | E9: BOUMEZGANE SOUKAINA | F9: 45294 | G9: AFEDIM | H9: 06 96 58 34 55 | I9: SALE | J9: ROND POINT HALIMA ROUTE DE KENITRA | K9: ZONE 4 | L9: 08H | M9: 18H | N9: 08H | O9: 18H | P9: 08H | Q9: 18H | R9: 08H | S9: 18H | T9: 08H | U9: 17H | V9: OFF | W9: OFF | X9: OFF | Y9: OFF
A10: S28 | B10: 1066 | C10: AIT RABIAA | D10: NOUHAILA | E10: AIT RABIAA NOUHAILA | F10: 45680 | G10: CM Leasing | H10: 06 24 56 94 36 | I10: SALE | J10: MOSQUEE TADAMOUN KARIA | K10: ZONE 5 | L10: 08H | M10: 18H | N10: 08H | O10: 18H | P10: 08H | Q10: 18H | R10: 08H | S10: 18H | T10: 08H | U10: 17H | V10: OFF | W10: OFF | X10: OFF | Y10: OFF
A11: S28 | B11: 1004 | C11: EL MAHJOUBI | D11: ABDESSATAR | E11: EL MAHJOUBI ABDESSATAR | F11: 45565 | G11: CM Leasing | H11: 06 14 40 31 57 | I11: TEMARA | J11: CAFE FELICITA | K11: ZONE 6 | L11: 08H | M11: 18H | N11: 08H | O11: 18H | P11: 08H | Q11: 18H | R11: 08H | S11: 18H | T11: 08H | U11: 17H | V11: OFF | W11: OFF | X11: OFF | Y11: OFF
A12: S28 | B12: 948 | C12: IDELHAJ | D12: Meriem | E12: IDELHAJ Meriem | F12: 45425 | G12: CM Leasing | H12: 07 21 48 48 36 | I12: KENITRA | J12: BIR RAMI BANQUE POPULAIRE | K12: ZONE 7 | L12: 08H | M12: 18H | N12: 08H | O12: 18H | P12: 08H | Q12: 18H | R12: 08H | S12: 18H | T12: 08H | U12: 17H | V12: OFF | W12: OFF | X12: OFF | Y12: OFF
A13: S28 | B13: 1011 | C13: LEHMOUCH | D13: NOUHAILA | E13: LEHMOUCH NOUHAILA | F13: 45565 | G13: CM Leasing | H13: 06 84 55 52 36 | I13: KENITRA | J13: MOSQUEE SALAM | K13: ZONE 7 | L13: 08H | M13: 18H | N13: 08H | O13: 18H | P13: 08H | Q13: 18H | R13: 08H | S13: 18H | T13: 08H | U13: 17H | V13: OFF | W13: OFF | X13: OFF | Y13: OFF
A14: S28 | B14: 1068 | C14: NOUIBI | D14: CHAIMAE | E14: NOUIBI CHAIMAE | F14: 45680 | G14: CM Leasing | H14: 06 01 70 00 00 | I14: TEMARA | J14: LES ECOLES SCIENTIFIQUES | K14: ZONE 6 | L14: 08H | M14: 18H | N14: 08H | O14: 18H | P14: 08H | Q14: 18H | R14: 08H | S14: 18H | T14: 08H | U14: 17H | V14: OFF | W14: OFF | X14: OFF | Y14: OFF
A15: S28 | B15: 1151 | C15: ESSABERY | D15: ISMAIL | E15: ESSABERY ISMAIL | F15: 45805 | G15: CM Leasing | H15: 06 76 05 93 30 | I15: RABAT | J15: DHL AGDAL | K15: ZONE 2 | L15: 08H | M15: 18H | N15: 08H | O15: 18H | P15: 08H | Q15: 18H | R15: 08H | S15: 18H | T15: 08H | U15: 17H | V15: OFF | W15: OFF | X15: OFF | Y15: OFF
A16: S28 | B16: 1300 | C16: AKHSASS | D16: MAJDA | E16: AKHSASS MAJDA | F16: 45895 | G16: CM Leasing | H16: 06 30 28 86 25 | I16: SALE | J16: MARJANE SALE | K16: ZONE 3 | L16: 08H | M16: 18H | N16: 08H | O16: 18H | P16: 08H | Q16: 18H | R16: 08H | S16: 18H | T16: 08H | U16: 17H | V16: OFF | W16: OFF | X16: OFF | Y16: OFF
A17: S28 | B17: 1301 | C17: JALAL | D17: NABILA | E17: JALAL NABILA | F17: 45895 | G17: CM Leasing | H17: 06 21 69 99 53 | I17: RABAT | J17: LA GARE AGDAL AV HASSAN II | K17: ZONE 2 | L17: 08H | M17: 18H | N17: 08H | O17: 18H | P17: 08H | Q17: 18H | R17: 08H | S17: 18H | T17: 08H | U17: 17H | V17: OFF | W17: OFF | X17: OFF | Y17: OFF
A18: S28 | B18: 1283 | C18: LAKHAL | D18: MEHDI | E18: LAKHAL MEHDI | F18: 45895 | G18: CM Leasing | H18: 06 96 52 40 37 | I18: KENITRA | J18: MOSQUEE SALAM | K18: ZONE 7 | L18: 08H | M18: 18H | N18: 08H | O18: 18H | P18: 08H | Q18: 18H | R18: 08H | S18: 18H | T18: 08H | U18: 17H | V18: OFF | W18: OFF | X18: OFF | Y18: OFF
A19: S28 | B19: 1309 | C19: SAADA | D19: LINA | E19: SAADA LINA | F19: 45903 | G19: CM Leasing | H19: 06 84 21 92 71 | I19: SALE | J19: BOULANGERIE BREAD HOUSE PRÈS DU ROND‐POINT CARREFOUR SALÉ | K19: ZONE 4 | L19: 08H | M19: 18H | N19: 08H | O19: 18H | P19: 08H | Q19: 18H | R19: 08H | S19: 18H | T19: 08H | U19: 17H | V19: OFF | W19: OFF | X19: OFF | Y19: OFF
A20: S28 | C20: HMIDI | D20: KHADIJA | E20: HMIDI KHADIJA | F20: 46077 | G20: CM Leasing | H20: 07 79 40 60 55 | I20: SALE | J20: kwass kenitra | K20: ZONE 4 | L20: 08H | M20: 18H | N20: 08H | O20: 18H | P20: 08H | Q20: 18H | R20: 08H | S20: 18H | T20: 08H | U20: 17H | V20: OFF | W20: OFF | X20: OFF | Y20: OFF
A21: S28 | C21: ELOUAHHABY | D21: DOUAAE | E21: ELOUAHHABY DOUAAE | F21: 46077 | G21: CM Leasing | H21: 06 19 63 47 77 | I21: SALE | J21: REDAL SAID HAJJI | K21: ZONE 4 | L21: 08H | M21: 18H | N21: 08H | O21: 18H | P21: 08H | Q21: 18H | R21: 08H | S21: 18H | T21: 08H | U21: 17H | V21: OFF | W21: OFF | X21: OFF | Y21: OFF
A22: S28 | C22: KHAN | D22: NIZAMUDDIN | E22: KHAN NIZAMUDDIN | F22: 46104 | G22: COFIDIS Espagne | H22: 06 16 50 25 60 | I22: SALE | J22: BIM LAAYAYDA | K22: ZONE 3 | L22: 07H | M22: 17H | N22: 07H | O22: 17H | P22: 07H | Q22: 17H | R22: 07H | S22: 17H | T22: 07H | U22: 16H | V22: OFF | W22: OFF | X22: OFF | Y22: OFF
A23: S28 | C23: TAIK | D23: HAMDANE | E23: TAIK HAMDANE | F23: 46104 | G23: COFIDIS Espagne | H23: 06 59 95 43 09 | I23: SALE | J23: MARJANE HAY KARIMA SALE | K23: ZONE 4 | L23: 08H | M23: 18H | N23: 08H | O23: 18H | P23: 08H | Q23: 18H | R23: 08H | S23: 18H | T23: 08H | U23: 17H | V23: OFF | W23: OFF | X23: OFF | Y23: OFF
A24: S28 | C24: ZTAIT | D24: NAJLAE | E24: ZTAIT NAJLAE | F24: 46104 | G24: COFIDIS Espagne | H24: 06 61 94 14 20 | I24: SALE | J24: REDAL SAID HAJJI | K24: ZONE 4 | L24: 07H | M24: 17H | N24: 07H | O24: 17H | P24: 07H | Q24: 17H | R24: 07H | S24: 17H | T24: 07H | U24: 16H | V24: OFF | W24: OFF | X24: OFF | Y24: OFF
A25: S28 | C25: GAYER | D25: YASSER | E25: GAYER YASSER | F25: 46104 | G25: COFIDIS Espagne | H25: 06 22 79 25 76 | I25: RABAT | J25: RESIDENCE SAADA | K25: ZONE 1 | L25: 08H | M25: 18H | N25: 08H | O25: 18H | P25: 08H | Q25: 18H | R25: 08H | S25: 18H | T25: 08H | U25: 17H | V25: OFF | W25: OFF | X25: OFF | Y25: OFF
A26: S28 | C26: AGNABER | D26: HANAE | E26: AGNABER HANAE | F26: 46104 | G26: COFIDIS Espagne | H26: 06 08 48 94 02 | I26: TEMARA | J26: BOULENGERIE OUHOUD | K26: ZONE 6 | L26: 08H | M26: 18H | N26: 08H | O26: 18H | P26: 08H | Q26: 18H | R26: 08H | S26: 18H | T26: 08H | U26: 17H | V26: OFF | W26: OFF | X26: OFF | Y26: OFF
A27: S28 | C27: ZOUAKAT | D27: ABDEL ILLAH | E27: ZOUAKAT ABDEL ILLAH | F27: 46104 | G27: COFIDIS Espagne | H27: 06 48 90 86 96 | I27: SALE | J27: BIM LAAYAYDA | K27: ZONE 3 | L27: 07H | M27: 17H | N27: 07H | O27: 17H | P27: 07H | Q27: 17H | R27: 07H | S27: 17H | T27: 07H | U27: 16H | V27: OFF | W27: OFF | X27: OFF | Y27: OFF
A28: S28 | C28: LAMKHIAR | D28: NABIL | E28: LAMKHIAR NABIL | F28: 46125 | G28: COFIDIS Espagne | H28: 06 43 30 12 21 | I28: KENITRA | J28: LA GARE KENITRA | K28: ZONE 8 | L28: 08H | M28: 18H | N28: 08H | O28: 18H | P28: 08H | Q28: 18H | R28: 08H | S28: 18H | T28: 08H | U28: 17H | V28: OFF | W28: OFF | X28: OFF | Y28: OFF
A29: S28 | C29: EL MORABIT | D29: JAMAL DINNE | E29: EL MORABIT JAMAL DINNE | F29: 46125 | G29: COFIDIS Espagne | H29: 06 36 84 91 92 | I29: RABAT | J29: EN FACE SNACK EL OUAZZANI AGDAL | K29: ZONE 2 | L29: 08H | M29: 18H | N29: 08H | O29: 18H | P29: 08H | Q29: 18H | R29: 08H | S29: 18H | T29: 08H | U29: 17H | V29: OFF | W29: OFF | X29: OFF | Y29: OFF
A30: S28 | B30: 1058 | C30: ABBASSI | D30: YASSIR | E30: ABBASSI YASSIR | F30: 45663 | G30: COFIDIS FRANCE | H30: 06 47 97 96 44 | I30: TEMARA | J30: MOSQUEE ABOU HOURAIRA | K30: ZONE 6 | L30: OFF | M30: OFF | N30: OFF | O30: OFF | P30: OFF | Q30: OFF | R30: OFF | S30: OFF | T30: OFF | U30: OFF | V30: OFF | W30: OFF | X30: OFF | Y30: OFF
A31: S28 | B31: 1376 | C31: ABBOUCHA | D31: NADA | E31: ABBOUCHA NADA | F31: 45978 | G31: COFIDIS FRANCE | H31: 07 75 33 38 58 | I31: SALE | J31: SUPER HAY RAHMA | K31: ZONE 3 | L31: 07H | M31: 17H | N31: 07H | O31: 17H | P31: OFF | Q31: OFF | R31: 07H | S31: 17H | T31: 07H | U31: 17H | V31: 07H | W31: 13H | X31: OFF | Y31: OFF
A32: S28 | B32: 1060 | C32: AIT ALI | D32: LOUBNA | E32: AIT ALI LOUBNA | F32: 45663 | G32: COFIDIS FRANCE | H32: 06 60 64 89 02 | I32: KENITRA | J32: SURETE NATIONAL CENTRALE DE KENITRA | K32: ZONE 8 | L32: 08H | M32: 18H | N32: 08H | O32: 18H | P32: 08H | Q32: 18H | R32: 08H | S32: 18H | T32: 09H | U32: 18H | V32: OFF | W32: OFF | X32: OFF | Y32: OFF
A33: S28 | B33: 1105 | C33: ALAOUI M'HAMDI | D33: EL HASSAN | E33: ALAOUI M'HAMDI EL HASSAN | F33: 45719 | G33: COFIDIS FRANCE | H33: 06 21 85 38 60 | I33: SALE | J33: REGIE TABAC SALE | K33: ZONE 4 | L33: 07H | M33: 17H | N33: 07H | O33: 17H | P33: 08H | Q33: 18H | R33: 08H | S33: 18H | T33: OFF | U33: OFF | V33: 07H | W33: 13H | X33: OFF | Y33: OFF
A34: S28 | B34: 1137 | C34: BA | D34: THIERNO HAMDOU | E34: BA THIERNO HAMDOU | F34: 45805 | G34: COFIDIS FRANCE | H34: 06 48 64 02 75 | I34: TEMARA | J34: STATION CHIGUA | K34: ZONE 6 | L34: 07H | M34: 17H | N34: OFF | O34: OFF | P34: 07H | Q34: 17H | R34: 07H | S34: 17H | T34: 07H | U34: 17H | V34: 07H | W34: 13H | X34: OFF | Y34: OFF
A35: S28 | B35: 126 | C35: BAYEZ | D35: LAMYAE | E35: BAYEZ LAMYAE | F35: 43753 | G35: COFIDIS FRANCE | H35: 06 89 68 10 24 | I35: RABAT | J35: ROND POINT AL MANAL | K35: ZONE 1 | L35: 07H | M35: 17H | N35: OFF | O35: OFF | P35: 08H | Q35: 18H | R35: 08H | S35: 18H | T35: 08H | U35: 18H | V35: 07H | W35: 13H | X35: OFF | Y35: OFF
A36: S28 | B36: 937 | C36: BELKHEIRFIH | D36: ZINEB | E36: BELKHEIRFIH ZINEB | F36: 45357 | G36: COFIDIS FRANCE | H36: 07 15 66 59 09 | I36: KENITRA | J36: BANQUE POPULAIRE BIR RAMI | K36: ZONE 8 | L36: 07H | M36: 17H | N36: 07H | O36: 17H | P36: OFF | Q36: OFF | R36: 07H | S36: 17H | T36: 07H | U36: 17H | V36: 07H | W36: 13H | X36: OFF | Y36: OFF
A37: S28 | B37: 1267 | C37: BELLARAJ | D37: ILHAME | E37: BELLARAJ ILHAME | F37: 45895 | G37: COFIDIS FRANCE | H37: 07 63 13 03 14 | I37: TEMARA | J37: CAFE ZAGOURA MASSIRA 1 | K37: ZONE 6 | L37: 08H | M37: 18H | N37: 08H | O37: 18H | P37: 07H | Q37: 17H | R37: 07H | S37: 17H | T37: OFF | U37: OFF | V37: 07H | W37: 13H | X37: OFF | Y37: OFF
A38: S28 | B38: 674 | C38: BEL-MALEM | D38: MERIEM | E38: BEL-MALEM MERIEM | F38: 44655 | G38: COFIDIS FRANCE | H38: 06 77 51 27 80 | I38: SALE | J38: EN FACE RESIDENCE ANNAKHIL | K38: ZONE 4 | L38: OFF | M38: OFF | N38: OFF | O38: OFF | P38: OFF | Q38: OFF | R38: OFF | S38: OFF | T38: OFF | U38: OFF | V38: OFF | W38: OFF | X38: OFF | Y38: OFF
A39: S28 | B39: 153 | C39: BELQASMI | D39: EL MEHDI | E39: BELQASMI EL MEHDI | F39: 43776 | G39: COFIDIS FRANCE | H39: 06 15 47 84 06 | I39: KENITRA | J39: CAFE HSSINA | K39: ZONE 8 | L39: 07H | M39: 16H | N39: 07H | O39: 16H | P39: 07H | Q39: 16H | R39: 07H | S39: 16H | T39: 07H | U39: 16H | V39: OFF | W39: OFF | X39: OFF | Y39: OFF
A40: S28 | B40: 1121 | C40: BENHMIDOU | D40: Jihane | E40: BENHMIDOU Jihane | F40: 45721 | G40: COFIDIS FRANCE | H40: 06 90 91 01 52 | I40: TEMARA | J40: CAFE BAVARIA /BMCI | K40: ZONE 6 | L40: 08H | M40: 18H | N40: 07H | O40: 17H | P40: 07H | Q40: 17H | R40: OFF | S40: OFF | T40: 07H | U40: 17H | V40: 07H | W40: 13H | X40: OFF | Y40: OFF
...

Sheet ETAT
A4: Entrées | L4: SORTIES
A5: IPUR | B5: VILLE | C5: 06H | D5: 06H | E5: 07H | F5: 08H | G5: 09H | H5: 10H | I5: 11H | J5: 12H | L5: IPUR | M5: VILLE | N5: 11H | O5: 12H | P5: 13H | Q5: 14H | R5: 15H | S5: 16H | T5: 17H | U5: 18H | V5: 19H | W5: 20H
A6: LUNDI | B6: KENITRA | C6: =COUNTIFS(PLANNING!$I:$I,ETAT!$B6,PLANNING!$L:$L,C$5) -> 0 | D6: =COUNTIFS(PLANNING!$I:$I,ETAT!$B6,PLANNING!$L:$L,D$5) -> 0 | E6: =COUNTIFS(PLANNING!$I:$I,ETAT!$B6,PLANNING!$L:$L,E$5) -> 17 | F6: =COUNTIFS(PLANNING!$I:$I,ETAT!$B6,PLANNING!$L:$L,F$5) -> 30 | G6: =COUNTIFS(PLANNING!$I:$I,ETAT!$B6,PLANNING!$L:$L,G$5) -> 0 | H6: =COUNTIFS(PLANNING!$I:$I,ETAT!$B6,PLANNING!$L:$L,H$5) -> 4 | I6: =COUNTIFS(PLANNING!$I:$I,ETAT!$B6,PLANNING!$L:$L,I$5) -> 0 | J6: =COUNTIFS(PLANNING!$I:$I,ETAT!$B6,PLANNING!$L:$L,J$5) -> 0 | L6: LUNDI | M6: KENITRA | N6: =COUNTIFS(PLANNING!$I:$I,$B6,PLANNING!$M:$M,N$5) -> 0 | O6: =COUNTIFS(PLANNING!$I:$I,$B6,PLANNING!$M:$M,O$5) -> 0 | P6: =COUNTIFS(PLANNING!$I:$I,$B6,PLANNING!$M:$M,P$5) -> 0 | Q6: =COUNTIFS(PLANNING!$I:$I,$B6,PLANNING!$M:$M,Q$5) -> 0 | R6: =COUNTIFS(PLANNING!$I:$I,$B6,PLANNING!$M:$M,R$5) -> 0 | S6: =COUNTIFS(PLANNING!$I:$I,$B6,PLANNING!$M:$M,S$5) -> 5 | T6: =COUNTIFS(PLANNING!$I:$I,$B6,PLANNING!$M:$M,T$5) -> 25 | U6: =COUNTIFS(PLANNING!$I:$I,$B6,PLANNING!$M:$M,U$5) -> 17 | ... W6: =COUNTIFS(PLANNING!$I:$I,$B6,PLANNING!$M:$M,W$5) -> 4
A7: LUNDI | B7: RABAT | C7: =COUNTIFS(PLANNING!$I:$I,$B7,PLANNING!$L:$L,C$5) -> 0 | D7: =COUNTIFS(PLANNING!$I:$I,$B7,PLANNING!$L:$L,D$5) -> 0 | E7: =COUNTIFS(PLANNING!$I:$I,$B7,PLANNING!$L:$L,E$5) -> 21 | F7: =COUNTIFS(PLANNING!$I:$I,$B7,PLANNING!$L:$L,F$5) -> 19 | G7: =COUNTIFS(PLANNING!$I:$I,$B7,PLANNING!$L:$L,G$5) -> 0 | H7: =COUNTIFS(PLANNING!$I:$I,$B7,PLANNING!$L:$L,H$5) -> 0 | I7: =COUNTIFS(PLANNING!$I:$I,$B7,PLANNING!$L:$L,I$5) -> 0 | J7: =COUNTIFS(PLANNING!$I:$I,$B7,PLANNING!$L:$L,J$5) -> 0 | L7: LUNDI | M7: RABAT | N7: =COUNTIFS(PLANNING!$I:$I,$B7,PLANNING!$M:$M,N$5) -> 0 | O7: =COUNTIFS(PLANNING!$I:$I,$B7,PLANNING!$M:$M,O$5) -> 0 | P7: =COUNTIFS(PLANNING!$I:$I,$B7,PLANNING!$M:$M,P$5) -> 0 | Q7: =COUNTIFS(PLANNING!$I:$I,$B7,PLANNING!$M:$M,Q$5) -> 0 | R7: =COUNTIFS(PLANNING!$I:$I,$B7,PLANNING!$M:$M,R$5) -> 0 | S7: =COUNTIFS(PLANNING!$I:$I,$B7,PLANNING!$M:$M,S$5) -> 4 | T7: =COUNTIFS(PLANNING!$I:$I,$B7,PLANNING!$M:$M,T$5) -> 24 | U7: =COUNTIFS(PLANNING!$I:$I,$B7,PLANNING!$M:$M,U$5) -> 12 | ... W7: =COUNTIFS(PLANNING!$I:$I,$B7,PLANNING!$M:$M,W$5) -> 0
A8: LUNDI | B8: SALE SALA AL JADIDA | C8: =COUNTIFS(PLANNING!$I:$I,LEFT($B$8,4),PLANNING!$L:$L,C$5)+COUNTIFS(PLANNING!$I:$I,RIGHT($B$8,14),PLANNING!$L:$L,C$5) -> 0 | D8: =COUNTIFS(PLANNING!$I:$I,LEFT($B$8,4),PLANNING!$L:$L,D$5)+COUNTIFS(PLANNING!$I:$I,RIGHT($B$8,14),PLANNING!$L:$L,D$5) -> 0 | E8: =COUNTIFS(PLANNING!$I:$I,LEFT($B$8,4),PLANNING!$L:$L,E$5)+COUNTIFS(PLANNING!$I:$I,RIGHT($B$8,14),PLANNING!$L:$L,E$5) -> 36 | F8: =COUNTIFS(PLANNING!$I:$I,LEFT($B$8,4),PLANNING!$L:$L,F$5)+COUNTIFS(PLANNING!$I:$I,RIGHT($B$8,14),PLANNING!$L:$L,F$5) -> 69 | G8: =COUNTIFS(PLANNING!$I:$I,LEFT($B$8,4),PLANNING!$L:$L,G$5)+COUNTIFS(PLANNING!$I:$I,RIGHT($B$8,14),PLANNING!$L:$L,G$5) -> 19 | H8: =COUNTIFS(PLANNING!$I:$I,LEFT($B$8,4),PLANNING!$L:$L,H$5)+COUNTIFS(PLANNING!$I:$I,RIGHT($B$8,14),PLANNING!$L:$L,H$5) -> 6 | I8: =COUNTIFS(PLANNING!$I:$I,LEFT($B$8,4),PLANNING!$L:$L,I$5)+COUNTIFS(PLANNING!$I:$I,RIGHT($B$8,14),PLANNING!$L:$L,I$5) -> 0 | J8: =COUNTIFS(PLANNING!$I:$I,LEFT($B$8,4),PLANNING!$L:$L,J$5)+COUNTIFS(PLANNING!$I:$I,RIGHT($B$8,14),PLANNING!$L:$L,J$5) -> 0 | L8: LUNDI | M8: SALE SALA AL JADIDA | N8: =COUNTIFS(PLANNING!$I:$I,LEFT($B$8,4),PLANNING!$M:$M,N$5)+COUNTIFS(PLANNING!$I:$I,RIGHT($B$8,14),PLANNING!$M:$M,N$5) -> 0 | O8: =COUNTIFS(PLANNING!$I:$I,LEFT($B$8,4),PLANNING!$M:$M,O$5)+COUNTIFS(PLANNING!$I:$I,RIGHT($B$8,14),PLANNING!$M:$M,O$5) -> 0 | P8: =COUNTIFS(PLANNING!$I:$I,LEFT($B$8,4),PLANNING!$M:$M,P$5)+COUNTIFS(PLANNING!$I:$I,RIGHT($B$8,14),PLANNING!$M:$M,P$5) -> 0 | Q8: =COUNTIFS(PLANNING!$I:$I,LEFT($B$8,4),PLANNING!$M:$M,Q$5)+COUNTIFS(PLANNING!$I:$I,RIGHT($B$8,14),PLANNING!$M:$M,Q$5) -> 0 | R8: =COUNTIFS(PLANNING!$I:$I,LEFT($B$8,4),PLANNING!$M:$M,R$5)+COUNTIFS(PLANNING!$I:$I,RIGHT($B$8,14),PLANNING!$M:$M,R$5) -> 0 | S8: =COUNTIFS(PLANNING!$I:$I,LEFT($B$8,4),PLANNING!$M:$M,S$5)+COUNTIFS(PLANNING!$I:$I,RIGHT($B$8,14),PLANNING!$M:$M,S$5) -> 18 | T8: =COUNTIFS(PLANNING!$I:$I,LEFT($B$8,4),PLANNING!$M:$M,T$5)+COUNTIFS(PLANNING!$I:$I,RIGHT($B$8,14),PLANNING!$M:$M,T$5) -> 41 | U8: =COUNTIFS(PLANNING!$I:$I,LEFT($B$8,4),PLANNING!$M:$M,U$5)+COUNTIFS(PLANNING!$I:$I,RIGHT($B$8,14),PLANNING!$M:$M,U$5) -> 48 | ... W8: =COUNTIFS(PLANNING!$I:$I,LEFT($B$8,4),PLANNING!$M:$M,W$5)+COUNTIFS(PLANNING!$I:$I,RIGHT($B$8,14),PLANNING!$M:$M,W$5) -> 6
A9: LUNDI | B9: TEMARA | C9: =COUNTIFS(PLANNING!$I:$I,$B9,PLANNING!$L:$L,C$5) -> 0 | D9: =COUNTIFS(PLANNING!$I:$I,$B9,PLANNING!$L:$L,D$5) -> 0 | E9: =COUNTIFS(PLANNING!$I:$I,$B9,PLANNING!$L:$L,E$5) -> 13 | F9: =COUNTIFS(PLANNING!$I:$I,$B9,PLANNING!$L:$L,F$5) -> 27 | G9: =COUNTIFS(PLANNING!$I:$I,$B9,PLANNING!$L:$L,G$5) -> 0 | H9: =COUNTIFS(PLANNING!$I:$I,$B9,PLANNING!$L:$L,H$5) -> 0 | I9: =COUNTIFS(PLANNING!$I:$I,$B9,PLANNING!$L:$L,I$5) -> 0 | J9: =COUNTIFS(PLANNING!$I:$I,$B9,PLANNING!$L:$L,J$5) -> 0 | L9: LUNDI | M9: TEMARA | N9: =COUNTIFS(PLANNING!$I:$I,$B9,PLANNING!$M:$M,N$5) -> 0 | O9: =COUNTIFS(PLANNING!$I:$I,$B9,PLANNING!$M:$M,O$5) -> 0 | P9: =COUNTIFS(PLANNING!$I:$I,$B9,PLANNING!$M:$M,P$5) -> 0 | Q9: =COUNTIFS(PLANNING!$I:$I,$B9,PLANNING!$M:$M,Q$5) -> 0 | R9: =COUNTIFS(PLANNING!$I:$I,LEFT($B$9,4),PLANNING!$M:$M,R$5)+COUNTIFS(PLANNING!$I:$I,RIGHT($B$9,14),PLANNING!$M:$M,R$5) -> 0 | S9: =COUNTIFS(PLANNING!$I:$I,$B9,PLANNING!$M:$M,S$5) -> 6 | T9: =COUNTIFS(PLANNING!$I:$I,$B9,PLANNING!$M:$M,T$5) -> 11 | U9: =COUNTIFS(PLANNING!$I:$I,$B9,PLANNING!$M:$M,U$5) -> 23 | V9: =COUNTIFS(PLANNING!$I:$I,$B9,PLANNING!$M:$M,V$5) -> 0 | W9: =COUNTIFS(PLANNING!$I:$I,$B9,PLANNING!$M:$M,W$5) -> 0
A10: MARDI | B10: KENITRA | C10: =COUNTIFS(PLANNING!$I:$I,$B10,PLANNING!$N:$N,C$5) -> 0 | D10: =COUNTIFS(PLANNING!$I:$I,$B10,PLANNING!$N:$N,D$5) -> 0 | E10: =COUNTIFS(PLANNING!$I:$I,$B10,PLANNING!$N:$N,E$5) -> 15 | F10: =COUNTIFS(PLANNING!$I:$I,$B10,PLANNING!$N:$N,F$5) -> 18 | G10: =COUNTIFS(PLANNING!$I:$I,$B10,PLANNING!$N:$N,G$5) -> 0 | H10: =COUNTIFS(PLANNING!$I:$I,$B10,PLANNING!$M:$M,H$5) -> 0 | I10: =COUNTIFS(PLANNING!$I:$I,$B10,PLANNING!$M:$M,I$5) -> 0 | J10: =COUNTIFS(PLANNING!$I:$I,$B10,PLANNING!$M:$M,J$5) -> 0 | L10: MARDI | M10: KENITRA | N10: =COUNTIFS(PLANNING!$I:$I,$B10,PLANNING!$O:$O,N$5) -> 0 | O10: =COUNTIFS(PLANNING!$I:$I,$B10,PLANNING!$O:$O,O$5) -> 0 | P10: =COUNTIFS(PLANNING!$I:$I,$B10,PLANNING!$O:$O,P$5) -> 0 | Q10: =COUNTIFS(PLANNING!$I:$I,$B10,PLANNING!$O:$O,Q$5) -> 0 | R10: =COUNTIFS(PLANNING!$I:$I,$B10,PLANNING!$O:$O,R$5) -> 0 | S10: =COUNTIFS(PLANNING!$I:$I,$B10,PLANNING!$O:$O,S$5) -> 5 | T10: =COUNTIFS(PLANNING!$I:$I,$B10,PLANNING!$O:$O,T$5) -> 13 | U10: =COUNTIFS(PLANNING!$I:$I,$B10,PLANNING!$O:$O,U$5) -> 15 | ... W10: =COUNTIFS(PLANNING!$I:$I,$B10,PLANNING!$O:$O,W$5) -> 15
A11: MARDI | B11: RABAT | C11: =COUNTIFS(PLANNING!$I:$I,$B11,PLANNING!$N:$N,C$5) -> 0 | D11: =COUNTIFS(PLANNING!$I:$I,$B11,PLANNING!$N:$N,D$5) -> 0 | E11: =COUNTIFS(PLANNING!$I:$I,$B11,PLANNING!$N:$N,E$5) -> 19 | F11: =COUNTIFS(PLANNING!$I:$I,$B11,PLANNING!$N:$N,F$5) -> 16 | G11: =COUNTIFS(PLANNING!$I:$I,$B11,PLANNING!$N:$N,G$5) -> 0 | H11: =COUNTIFS(PLANNING!$I:$I,$B11,PLANNING!$N:$N,H$5) -> 2 | I11: =COUNTIFS(PLANNING!$I:$I,$B11,PLANNING!$M:$M,I$5) -> 0 | J11: =COUNTIFS(PLANNING!$I:$I,$B11,PLANNING!$M:$M,J$5) -> 0 | L11: MARDI | M11: RABAT | N11: =COUNTIFS(PLANNING!$I:$I,$B11,PLANNING!$O:$O,N$5) -> 0 | O11: =COUNTIFS(PLANNING!$I:$I,$B11,PLANNING!$O:$O,O$5) -> 0 | P11: =COUNTIFS(PLANNING!$I:$I,$B11,PLANNING!$O:$O,P$5) -> 0 | Q11: =COUNTIFS(PLANNING!$I:$I,$B11,PLANNING!$O:$O,Q$5) -> 0 | R11: =COUNTIFS(PLANNING!$I:$I,$B11,PLANNING!$O:$O,R$5) -> 0 | S11: =COUNTIFS(PLANNING!$I:$I,$B11,PLANNING!$O:$O,S$5) -> 3 | T11: =COUNTIFS(PLANNING!$I:$I,$B11,PLANNING!$O:$O,T$5) -> 21 | U11: =COUNTIFS(PLANNING!$I:$I,$B11,PLANNING!$O:$O,U$5) -> 11 | ... W11: =COUNTIFS(PLANNING!$I:$I,$B11,PLANNING!$O:$O,W$5) -> 2
A12: MARDI | B12: SALE SALA AL JADIDA | C12: =COUNTIFS(PLANNING!$I:$I,LEFT($B$8,4),PLANNING!$N:$N,C$5)+COUNTIFS(PLANNING!$I:$I,RIGHT($B$8,14),PLANNING!$N:$N,C$5) -> 0 | D12: =COUNTIFS(PLANNING!$I:$I,LEFT($B$8,4),PLANNING!$N:$N,D$5)+COUNTIFS(PLANNING!$I:$I,RIGHT($B$8,14),PLANNING!$N:$N,D$5) -> 0 | E12: =COUNTIFS(PLANNING!$I:$I,LEFT($B$8,4),PLANNING!$N:$N,E$5)+COUNTIFS(PLANNING!$I:$I,RIGHT($B$8,14),PLANNING!$N:$N,E$5) -> 37 | F12: =COUNTIFS(PLANNING!$I:$I,LEFT($B$8,4),PLANNING!$N:$N,F$5)+COUNTIFS(PLANNING!$I:$I,RIGHT($B$8,14),PLANNING!$N:$N,F$5) -> 50 | G12: =COUNTIFS(PLANNING!$I:$I,LEFT($B$8,4),PLANNING!$N:$N,G$5)+COUNTIFS(PLANNING!$I:$I,RIGHT($B$8,14),PLANNING!$N:$N,G$5) -> 19 | H12: =COUNTIFS(PLANNING!$I:$I,LEFT($B$8,4),PLANNING!$P:$P,H$5)+COUNTIFS(PLANNING!$I:$I,RIGHT($B$8,14),PLANNING!$P:$P,H$5) -> 14 | I12: =COUNTIFS(PLANNING!$I:$I,LEFT($B$8,4),PLANNING!$M:$M,I$5)+COUNTIFS(PLANNING!$I:$I,RIGHT($B$8,14),PLANNING!$M:$M,I$5) -> 0 | J12: =COUNTIFS(PLANNING!$I:$I,LEFT($B$8,4),PLANNING!$M:$M,J$5)+COUNTIFS(PLANNING!$I:$I,RIGHT($B$8,14),PLANNING!$M:$M,J$5) -> 0 | L12: MARDI | M12: SALE SALA AL JADIDA | N12: =COUNTIFS(PLANNING!$I:$I,LEFT($B$8,4),PLANNING!$O:$O,N$5)+COUNTIFS(PLANNING!$I:$I,RIGHT($B$8,14),PLANNING!$O:$O,N$5) -> 0 | O12: =COUNTIFS(PLANNING!$I:$I,LEFT($B$8,4),PLANNING!$O:$O,O$5)+COUNTIFS(PLANNING!$I:$I,RIGHT($B$8,14),PLANNING!$O:$O,O$5) -> 0 | P12: =COUNTIFS(PLANNING!$I:$I,LEFT($B$8,4),PLANNING!$O:$O,P$5)+COUNTIFS(PLANNING!$I:$I,RIGHT($B$8,14),PLANNING!$O:$O,P$5) -> 0 | Q12: =COUNTIFS(PLANNING!$I:$I,LEFT($B$8,4),PLANNING!$O:$O,Q$5)+COUNTIFS(PLANNING!$I:$I,RIGHT($B$8,14),PLANNING!$O:$O,Q$5) -> 0 | R12: =COUNTIFS(PLANNING!$I:$I,LEFT($B$8,4),PLANNING!$O:$O,R$5)+COUNTIFS(PLANNING!$I:$I,RIGHT($B$8,14),PLANNING!$O:$O,R$5) -> 0 | S12: =COUNTIFS(PLANNING!$I:$I,LEFT($B$8,4),PLANNING!$O:$O,S$5)+COUNTIFS(PLANNING!$I:$I,RIGHT($B$8,14),PLANNING!$O:$O,S$5) -> 18 | T12: =COUNTIFS(PLANNING!$I:$I,LEFT($B$8,4),PLANNING!$O:$O,T$5)+COUNTIFS(PLANNING!$I:$I,RIGHT($B$8,14),PLANNING!$O:$O,T$5) -> 22 | U12: =COUNTIFS(PLANNING!$I:$I,LEFT($B$8,4),PLANNING!$O:$O,U$5)+COUNTIFS(PLANNING!$I:$I,RIGHT($B$8,14),PLANNING!$O:$O,U$5) -> 49 | ... W12: =COUNTIFS(PLANNING!$I:$I,LEFT($B$8,4),PLANNING!$O:$O,W$5)+COUNTIFS(PLANNING!$I:$I,RIGHT($B$8,14),PLANNING!$O:$O,W$5) -> 24
A13: MARDI | B13: TEMARA | C13: =COUNTIFS(PLANNING!$I:$I,$B13,PLANNING!$N:$N,C$5) -> 0 | D13: =COUNTIFS(PLANNING!$I:$I,$B13,PLANNING!$N:$N,D$5) -> 0 | E13: =COUNTIFS(PLANNING!$I:$I,$B13,PLANNING!$N:$N,E$5) -> 13 | F13: =COUNTIFS(PLANNING!$I:$I,$B13,PLANNING!$N:$N,F$5) -> 25 | G13: =COUNTIFS(PLANNING!$I:$I,$B13,PLANNING!$N:$N,G$5) -> 0 | H13: =COUNTIFS(PLANNING!$I:$I,$B13,PLANNING!$M:$M,H$5) -> 0 | I13: =COUNTIFS(PLANNING!$I:$I,$B13,PLANNING!$M:$M,I$5) -> 0 | J13: =COUNTIFS(PLANNING!$I:$I,$B13,PLANNING!$M:$M,J$5) -> 0 | L13: MARDI | M13: TEMARA | N13: =COUNTIFS(PLANNING!$I:$I,$B13,PLANNING!$O:$O,N$5) -> 0 | O13: =COUNTIFS(PLANNING!$I:$I,$B13,PLANNING!$O:$O,O$5) -> 0 | P13: =COUNTIFS(PLANNING!$I:$I,$B13,PLANNING!$O:$O,P$5) -> 0 | Q13: =COUNTIFS(PLANNING!$I:$I,$B13,PLANNING!$O:$O,Q$5) -> 0 | R13: =COUNTIFS(PLANNING!$I:$I,$B13,PLANNING!$O:$O,R$5) -> 0 | S13: =COUNTIFS(PLANNING!$I:$I,$B13,PLANNING!$O:$O,S$5) -> 6 | T13: =COUNTIFS(PLANNING!$I:$I,$B13,PLANNING!$O:$O,T$5) -> 9 | U13: =COUNTIFS(PLANNING!$I:$I,$B13,PLANNING!$O:$O,U$5) -> 23 | ... W13: =COUNTIFS(PLANNING!$I:$I,$B13,PLANNING!$O:$O,W$5) -> 3
A14: MERCREDI | B14: KENITRA | C14: =COUNTIFS(PLANNING!$I:$I,$B14,PLANNING!$P:$P,C$5) -> 0 | D14: =COUNTIFS(PLANNING!$I:$I,$B14,PLANNING!$P:$P,D$5) -> 0 | E14: =COUNTIFS(PLANNING!$I:$I,$B14,PLANNING!$P:$P,E$5) -> 13 | F14: =COUNTIFS(PLANNING!$I:$I,$B14,PLANNING!$P:$P,F$5) -> 25 | G14: =COUNTIFS(PLANNING!$I:$I,$B14,PLANNING!$P:$P,G$5) -> 0 | H14: =COUNTIFS(PLANNING!$I:$I,$B14,PLANNING!$P:$P,H$5) -> 6 | I14: =COUNTIFS(PLANNING!$I:$I,$B14,PLANNING!$P:$P,I$5) -> 0 | J14: =COUNTIFS(PLANNING!$I:$I,$B14,PLANNING!$P:$P,J$5) -> 0 | L14: MERCREDI | M14: KENITRA | N14: =COUNTIFS(PLANNING!$I:$I,$B14,PLANNING!$Q:$Q,N$5) -> 0 | O14: =COUNTIFS(PLANNING!$I:$I,$B14,PLANNING!$Q:$Q,O$5) -> 0 | P14: =COUNTIFS(PLANNING!$I:$I,$B14,PLANNING!$Q:$Q,P$5) -> 0 | Q14: =COUNTIFS(PLANNING!$I:$I,$B14,PLANNING!$Q:$Q,Q$5) -> 0 | R14: =COUNTIFS(PLANNING!$I:$I,$B14,PLANNING!$Q:$Q,R$5) -> 0 | S14: =COUNTIFS(PLANNING!$I:$I,$B14,PLANNING!$Q:$Q,S$5) -> 5 | T14: =COUNTIFS(PLANNING!$I:$I,$B14,PLANNING!$Q:$Q,T$5) -> 13 | U14: =COUNTIFS(PLANNING!$I:$I,$B14,PLANNING!$Q:$Q,U$5) -> 20 | ... W14: =COUNTIFS(PLANNING!$I:$I,$B14,PLANNING!$Q:$Q,W$5) -> 6
A15: MERCREDI | B15: RABAT | C15: =COUNTIFS(PLANNING!$I:$I,$B15,PLANNING!$P:$P,C$5) -> 0 | D15: =COUNTIFS(PLANNING!$I:$I,$B15,PLANNING!$P:$P,D$5) -> 0 | E15: =COUNTIFS(PLANNING!$I:$I,$B15,PLANNING!$P:$P,E$5) -> 18 | F15: =COUNTIFS(PLANNING!$I:$I,$B15,PLANNING!$P:$P,F$5) -> 21 | G15: =COUNTIFS(PLANNING!$I:$I,$B15,PLANNING!$P:$P,G$5) -> 0 | H15: =COUNTIFS(PLANNING!$I:$I,$B15,PLANNING!$P:$P,H$5) -> 0 | I15: =COUNTIFS(PLANNING!$I:$I,$B15,PLANNING!$P:$P,I$5) -> 0 | J15: =COUNTIFS(PLANNING!$I:$I,$B15,PLANNING!$P:$P,J$5) -> 0 | L15: MERCREDI | M15: RABAT | N15: =COUNTIFS(PLANNING!$I:$I,$B15,PLANNING!$Q:$Q,N$5) -> 0 | O15: =COUNTIFS(PLANNING!$I:$I,$B15,PLANNING!$Q:$Q,O$5) -> 0 | P15: =COUNTIFS(PLANNING!$I:$I,$B15,PLANNING!$Q:$Q,P$5) -> 0 | Q15: =COUNTIFS(PLANNING!$I:$I,$B15,PLANNING!$Q:$Q,Q$5) -> 0 | R15: =COUNTIFS(PLANNING!$I:$I,$B15,PLANNING!$Q:$Q,R$5) -> 0 | S15: =COUNTIFS(PLANNING!$I:$I,$B15,PLANNING!$Q:$Q,S$5) -> 4 | T15: =COUNTIFS(PLANNING!$I:$I,$B15,PLANNING!$Q:$Q,T$5) -> 19 | U15: =COUNTIFS(PLANNING!$I:$I,$B15,PLANNING!$Q:$Q,U$5) -> 16 | ... W15: =COUNTIFS(PLANNING!$I:$I,$B15,PLANNING!$Q:$Q,W$5) -> 0
A16: MERCREDI | B16: SALE SALA AL JADIDA | C16: =COUNTIFS(PLANNING!$I:$I,LEFT($B$8,4),PLANNING!$P:$P,C$5)+COUNTIFS(PLANNING!$I:$I,RIGHT($B$8,14),PLANNING!$P:$P,C$5) -> 0 | D16: =COUNTIFS(PLANNING!$I:$I,LEFT($B$8,4),PLANNING!$P:$P,D$5)+COUNTIFS(PLANNING!$I:$I,RIGHT($B$8,14),PLANNING!$P:$P,D$5) -> 0 | E16: =COUNTIFS(PLANNING!$I:$I,LEFT($B$8,4),PLANNING!$P:$P,E$5)+COUNTIFS(PLANNING!$I:$I,RIGHT($B$8,14),PLANNING!$P:$P,E$5) -> 30 | F16: =COUNTIFS(PLANNING!$I:$I,LEFT($B$8,4),PLANNING!$P:$P,F$5)+COUNTIFS(PLANNING!$I:$I,RIGHT($B$8,14),PLANNING!$P:$P,F$5) -> 55 | G16: =COUNTIFS(PLANNING!$I:$I,LEFT($B$8,4),PLANNING!$P:$P,G$5)+COUNTIFS(PLANNING!$I:$I,RIGHT($B$8,14),PLANNING!$P:$P,G$5) -> 24 | H16: =COUNTIFS(PLANNING!$I:$I,LEFT($B$8,4),PLANNING!$P:$P,H$5)+COUNTIFS(PLANNING!$I:$I,RIGHT($B$8,14),PLANNING!$P:$P,H$5) -> 14 | I16: =COUNTIFS(PLANNING!$I:$I,LEFT($B$8,4),PLANNING!$P:$P,I$5)+COUNTIFS(PLANNING!$I:$I,RIGHT($B$8,14),PLANNING!$P:$P,I$5) -> 0 | J16: =COUNTIFS(PLANNING!$I:$I,LEFT($B$8,4),PLANNING!$P:$P,J$5)+COUNTIFS(PLANNING!$I:$I,RIGHT($B$8,14),PLANNING!$P:$P,J$5) -> 0 | L16: MERCREDI | M16: SALE SALA AL JADIDA | N16: =COUNTIFS(PLANNING!$I:$I,LEFT($B$8,4),PLANNING!$Q:$Q,N$5)+COUNTIFS(PLANNING!$I:$I,RIGHT($B$8,14),PLANNING!$Q:$Q,N$5) -> 0 | O16: =COUNTIFS(PLANNING!$I:$I,LEFT($B$8,4),PLANNING!$Q:$Q,O$5)+COUNTIFS(PLANNING!$I:$I,RIGHT($B$8,14),PLANNING!$Q:$Q,O$5) -> 0 | P16: =COUNTIFS(PLANNING!$I:$I,LEFT($B$8,4),PLANNING!$Q:$Q,P$5)+COUNTIFS(PLANNING!$I:$I,RIGHT($B$8,14),PLANNING!$Q:$Q,P$5) -> 0 | Q16: =COUNTIFS(PLANNING!$I:$I,LEFT($B$8,4),PLANNING!$Q:$Q,Q$5)+COUNTIFS(PLANNING!$I:$I,RIGHT($B$8,14),PLANNING!$Q:$Q,Q$5) -> 0 | R16: =COUNTIFS(PLANNING!$I:$I,LEFT($B$8,4),PLANNING!$Q:$Q,R$5)+COUNTIFS(PLANNING!$I:$I,RIGHT($B$8,14),PLANNING!$Q:$Q,R$5) -> 0 | S16: =COUNTIFS(PLANNING!$I:$I,LEFT($B$8,4),PLANNING!$Q:$Q,S$5)+COUNTIFS(PLANNING!$I:$I,RIGHT($B$8,14),PLANNING!$Q:$Q,S$5) -> 18 | T16: =COUNTIFS(PLANNING!$I:$I,LEFT($B$8,4),PLANNING!$Q:$Q,T$5)+COUNTIFS(PLANNING!$I:$I,RIGHT($B$8,14),PLANNING!$Q:$Q,T$5) -> 15 | U16: =COUNTIFS(PLANNING!$I:$I,LEFT($B$8,4),PLANNING!$Q:$Q,U$5)+COUNTIFS(PLANNING!$I:$I,RIGHT($B$8,14),PLANNING!$Q:$Q,U$5) -> 54 | ... W16: =COUNTIFS(PLANNING!$I:$I,LEFT($B$8,4),PLANNING!$Q:$Q,W$5)+COUNTIFS(PLANNING!$I:$I,RIGHT($B$8,14),PLANNING!$Q:$Q,W$5) -> 14
A17: MERCREDI | B17: TEMARA | C17: =COUNTIFS(PLANNING!$I:$I,$B17,PLANNING!$P:$P,C$5) -> 0 | D17: =COUNTIFS(PLANNING!$I:$I,$B17,PLANNING!$P:$P,D$5) -> 0 | E17: =COUNTIFS(PLANNING!$I:$I,$B17,PLANNING!$P:$P,E$5) -> 14 | F17: =COUNTIFS(PLANNING!$I:$I,$B17,PLANNING!$P:$P,F$5) -> 20 | G17: =COUNTIFS(PLANNING!$I:$I,$B17,PLANNING!$P:$P,G$5) -> 0 | H17: =COUNTIFS(PLANNING!$I:$I,$B17,PLANNING!$P:$P,H$5) -> 0 | I17: =COUNTIFS(PLANNING!$I:$I,$B17,PLANNING!$P:$P,I$5) -> 0 | J17: =COUNTIFS(PLANNING!$I:$I,$B17,PLANNING!$P:$P,J$5) -> 0 | L17: MERCREDI | M17: TEMARA | N17: =COUNTIFS(PLANNING!$I:$I,$B17,PLANNING!$Q:$Q,N$5) -> 0 | O17: =COUNTIFS(PLANNING!$I:$I,$B17,PLANNING!$Q:$Q,O$5) -> 0 | P17: =COUNTIFS(PLANNING!$I:$I,$B17,PLANNING!$Q:$Q,P$5) -> 0 | Q17: =COUNTIFS(PLANNING!$I:$I,$B17,PLANNING!$Q:$Q,Q$5) -> 0 | R17: =COUNTIFS(PLANNING!$I:$I,$B17,PLANNING!$Q:$Q,R$5) -> 0 | S17: =COUNTIFS(PLANNING!$I:$I,$B17,PLANNING!$Q:$Q,S$5) -> 6 | T17: =COUNTIFS(PLANNING!$I:$I,$B17,PLANNING!$Q:$Q,T$5) -> 11 | U17: =COUNTIFS(PLANNING!$I:$I,$B17,PLANNING!$Q:$Q,U$5) -> 17 | ... W17: =COUNTIFS(PLANNING!$I:$I,$B17,PLANNING!$Q:$Q,W$5) -> 0
A18: JEUDI | B18: KENITRA | C18: =COUNTIFS(PLANNING!$I:$I,$B18,PLANNING!$R:$R,C$5) -> 0 | D18: =COUNTIFS(PLANNING!$I:$I,$B18,PLANNING!$R:$R,D$5) -> 0 | E18: =COUNTIFS(PLANNING!$I:$I,$B18,PLANNING!$R:$R,E$5) -> 16 | F18: =COUNTIFS(PLANNING!$I:$I,$B18,PLANNING!$R:$R,F$5) -> 27 | G18: =COUNTIFS(PLANNING!$I:$I,$B18,PLANNING!$R:$R,G$5) -> 0 | H18: =COUNTIFS(PLANNING!$I:$I,$B18,PLANNING!$R:$R,H$5) -> 0 | I18: =COUNTIFS(PLANNING!$I:$I,$B18,PLANNING!$R:$R,I$5) -> 0 | J18: =COUNTIFS(PLANNING!$I:$I,$B18,PLANNING!$R:$R,J$5) -> 0 | L18: JEUDI | M18: KENITRA | N18: =COUNTIFS(PLANNING!$I:$I,$B18,PLANNING!$S:$S,N$5) -> 0 | O18: =COUNTIFS(PLANNING!$I:$I,$B18,PLANNING!$S:$S,O$5) -> 0 | P18: =COUNTIFS(PLANNING!$I:$I,$B18,PLANNING!$S:$S,P$5) -> 0 | Q18: =COUNTIFS(PLANNING!$I:$I,$B18,PLANNING!$S:$S,Q$5) -> 0 | R18: =COUNTIFS(PLANNING!$I:$I,$B18,PLANNING!$S:$S,R$5) -> 0 | S18: =COUNTIFS(PLANNING!$I:$I,$B18,PLANNING!$S:$S,S$5) -> 6 | T18: =COUNTIFS(PLANNING!$I:$I,$B18,PLANNING!$S:$S,T$5) -> 15 | U18: =COUNTIFS(PLANNING!$I:$I,$B18,PLANNING!$S:$S,U$5) -> 22 | ... W18: =COUNTIFS(PLANNING!$I:$I,$B18,PLANNING!$S:$S,W$5) -> 0
A19: JEUDI | B19: RABAT | C19: =COUNTIFS(PLANNING!$I:$I,$B19,PLANNING!$R:$R,C$5) -> 0 | D19: =COUNTIFS(PLANNING!$I:$I,$B19,PLANNING!$R:$R,D$5) -> 0 | E19: =COUNTIFS(PLANNING!$I:$I,$B19,PLANNING!$R:$R,E$5) -> 13 | F19: =COUNTIFS(PLANNING!$I:$I,$B19,PLANNING!$R:$R,F$5) -> 20 | G19: =COUNTIFS(PLANNING!$I:$I,$B19,PLANNING!$R:$R,G$5) -> 0 | H19: =COUNTIFS(PLANNING!$I:$I,$B19,PLANNING!$R:$R,H$5) -> 0 | I19: =COUNTIFS(PLANNING!$I:$I,$B19,PLANNING!$R:$R,I$5) -> 0 | J19: =COUNTIFS(PLANNING!$I:$I,$B19,PLANNING!$R:$R,J$5) -> 0 | L19: JEUDI | M19: RABAT | N19: =COUNTIFS(PLANNING!$I:$I,$B19,PLANNING!$S:$S,N$5) -> 0 | O19: =COUNTIFS(PLANNING!$I:$I,$B19,PLANNING!$S:$S,O$5) -> 0 | P19: =COUNTIFS(PLANNING!$I:$I,$B19,PLANNING!$S:$S,P$5) -> 0 | Q19: =COUNTIFS(PLANNING!$I:$I,$B19,PLANNING!$S:$S,Q$5) -> 0 | R19: =COUNTIFS(PLANNING!$I:$I,$B19,PLANNING!$S:$S,R$5) -> 0 | S19: =COUNTIFS(PLANNING!$I:$I,$B19,PLANNING!$S:$S,S$5) -> 2 | T19: =COUNTIFS(PLANNING!$I:$I,$B19,PLANNING!$S:$S,T$5) -> 16 | U19: =COUNTIFS(PLANNING!$I:$I,$B19,PLANNING!$S:$S,U$5) -> 15 | ... W19: =COUNTIFS(PLANNING!$I:$I,$B19,PLANNING!$S:$S,W$5) -> 0
A20: JEUDI | B20: SALE SALA AL JADIDA | C20: =COUNTIFS(PLANNING!$I:$I,LEFT($B$8,4),PLANNING!$R:$R,C$5)+COUNTIFS(PLANNING!$I:$I,RIGHT($B$8,14),PLANNING!$R:$R,C$5) -> 0 | D20: =COUNTIFS(PLANNING!$I:$I,LEFT($B$8,4),PLANNING!$R:$R,D$5)+COUNTIFS(PLANNING!$I:$I,RIGHT($B$8,14),PLANNING!$R:$R,D$5) -> 0 | E20: =COUNTIFS(PLANNING!$I:$I,LEFT($B$8,4),PLANNING!$R:$R,E$5)+COUNTIFS(PLANNING!$I:$I,RIGHT($B$8,14),PLANNING!$R:$R,E$5) -> 35 | F20: =COUNTIFS(PLANNING!$I:$I,LEFT($B$8,4),PLANNING!$R:$R,F$5)+COUNTIFS(PLANNING!$I:$I,RIGHT($B$8,14),PLANNING!$R:$R,F$5) -> 49 | G20: =COUNTIFS(PLANNING!$I:$I,LEFT($B$8,4),PLANNING!$R:$R,G$5)+COUNTIFS(PLANNING!$I:$I,RIGHT($B$8,14),PLANNING!$R:$R,G$5) -> 18 | H20: =COUNTIFS(PLANNING!$I:$I,LEFT($B$8,4),PLANNING!$R:$R,H$5)+COUNTIFS(PLANNING!$I:$I,RIGHT($B$8,14),PLANNING!$R:$R,H$5) -> 15 | I20: =COUNTIFS(PLANNING!$I:$I,LEFT($B$8,4),PLANNING!$R:$R,I$5)+COUNTIFS(PLANNING!$I:$I,RIGHT($B$8,14),PLANNING!$R:$R,I$5) -> 0 | J20: =COUNTIFS(PLANNING!$I:$I,LEFT($B$8,4),PLANNING!$R:$R,J$5)+COUNTIFS(PLANNING!$I:$I,RIGHT($B$8,14),PLANNING!$R:$R,J$5) -> 0 | L20: JEUDI | M20: SALE SALA AL JADIDA | N20: =COUNTIFS(PLANNING!$I:$I,LEFT($B$8,4),PLANNING!$S:$S,N$5)+COUNTIFS(PLANNING!$I:$I,RIGHT($B$8,14),PLANNING!$S:$S,N$5) -> 0 | O20: =COUNTIFS(PLANNING!$I:$I,LEFT($B$8,4),PLANNING!$S:$S,O$5)+COUNTIFS(PLANNING!$I:$I,RIGHT($B$8,14),PLANNING!$S:$S,O$5) -> 0 | P20: =COUNTIFS(PLANNING!$I:$I,LEFT($B$8,4),PLANNING!$S:$S,P$5)+COUNTIFS(PLANNING!$I:$I,RIGHT($B$8,14),PLANNING!$S:$S,P$5) -> 0 | Q20: =COUNTIFS(PLANNING!$I:$I,LEFT($B$8,4),PLANNING!$S:$S,Q$5)+COUNTIFS(PLANNING!$I:$I,RIGHT($B$8,14),PLANNING!$S:$S,Q$5) -> 0 | R20: =COUNTIFS(PLANNING!$I:$I,LEFT($B$8,4),PLANNING!$S:$S,R$5)+COUNTIFS(PLANNING!$I:$I,RIGHT($B$8,14),PLANNING!$S:$S,R$5) -> 0 | S20: =COUNTIFS(PLANNING!$I:$I,LEFT($B$8,4),PLANNING!$S:$S,S$5)+COUNTIFS(PLANNING!$I:$I,RIGHT($B$8,14),PLANNING!$S:$S,S$5) -> 19 | T20: =COUNTIFS(PLANNING!$I:$I,LEFT($B$8,4),PLANNING!$S:$S,T$5)+COUNTIFS(PLANNING!$I:$I,RIGHT($B$8,14),PLANNING!$S:$S,T$5) -> 20 | U20: =COUNTIFS(PLANNING!$I:$I,LEFT($B$8,4),PLANNING!$S:$S,U$5)+COUNTIFS(PLANNING!$I:$I,RIGHT($B$8,14),PLANNING!$S:$S,U$5) -> 49 | ... W20: =COUNTIFS(PLANNING!$I:$I,LEFT($B$8,4),PLANNING!$S:$S,W$5)+COUNTIFS(PLANNING!$I:$I,RIGHT($B$8,14),PLANNING!$S:$S,W$5) -> 15
A21: JEUDI | B21: TEMARA | C21: =COUNTIFS(PLANNING!$I:$I,$B21,PLANNING!$R:$R,C$5) -> 0 | D21: =COUNTIFS(PLANNING!$I:$I,$B21,PLANNING!$R:$R,D$5) -> 0 | E21: =COUNTIFS(PLANNING!$I:$I,$B21,PLANNING!$R:$R,E$5) -> 14 | F21: =COUNTIFS(PLANNING!$I:$I,$B21,PLANNING!$R:$R,F$5) -> 22 | G21: =COUNTIFS(PLANNING!$I:$I,$B21,PLANNING!$R:$R,G$5) -> 0 | H21: =COUNTIFS(PLANNING!$I:$I,$B21,PLANNING!$R:$R,H$5) -> 0 | I21: =COUNTIFS(PLANNING!$I:$I,$B21,PLANNING!$R:$R,I$5) -> 0 | J21: =COUNTIFS(PLANNING!$I:$I,$B21,PLANNING!$R:$R,J$5) -> 0 | L21: JEUDI | M21: TEMARA | N21: =COUNTIFS(PLANNING!$I:$I,$B21,PLANNING!$S:$S,N$5) -> 0 | O21: =COUNTIFS(PLANNING!$I:$I,$B21,PLANNING!$S:$S,O$5) -> 0 | P21: =COUNTIFS(PLANNING!$I:$I,$B21,PLANNING!$S:$S,P$5) -> 0 | Q21: =COUNTIFS(PLANNING!$I:$I,$B21,PLANNING!$S:$S,Q$5) -> 0 | R21: =COUNTIFS(PLANNING!$I:$I,$B21,PLANNING!$S:$S,R$5) -> 0 | S21: =COUNTIFS(PLANNING!$I:$I,$B21,PLANNING!$S:$S,S$5) -> 6 | T21: =COUNTIFS(PLANNING!$I:$I,$B21,PLANNING!$S:$S,T$5) -> 11 | U21: =COUNTIFS(PLANNING!$I:$I,$B21,PLANNING!$S:$S,U$5) -> 19 | ... W21: =COUNTIFS(PLANNING!$I:$I,$B21,PLANNING!$S:$S,W$5) -> 0
A22: VENDREDI | B22: KENITRA | C22: =COUNTIFS(PLANNING!$I:$I,$B22,PLANNING!$T:$T,C$5) -> 0 | D22: =COUNTIFS(PLANNING!$I:$I,$B22,PLANNING!$T:$T,D$5) -> 0 | E22: =COUNTIFS(PLANNING!$I:$I,$B22,PLANNING!$T:$T,E$5) -> 16 | F22: =COUNTIFS(PLANNING!$I:$I,$B22,PLANNING!$T:$T,F$5) -> 19 | G22: =COUNTIFS(PLANNING!$I:$I,$B22,PLANNING!$T:$T,G$5) -> 5 | H22: =COUNTIFS(PLANNING!$I:$I,$B22,PLANNING!$T:$T,H$5) -> 5 | I22: =COUNTIFS(PLANNING!$I:$I,$B22,PLANNING!$T:$T,I$5) -> 0 | J22: =COUNTIFS(PLANNING!$I:$I,$B22,PLANNING!$T:$T,J$5) -> 0 | L22: VENDREDI | M22: KENITRA | N22: =COUNTIFS(PLANNING!$I:$I,$B22,PLANNING!$U:$U,N$5) -> 0 | O22: =COUNTIFS(PLANNING!$I:$I,$B22,PLANNING!$U:$U,O$5) -> 0 | P22: =COUNTIFS(PLANNING!$I:$I,$B22,PLANNING!$U:$U,P$5) -> 0 | Q22: =COUNTIFS(PLANNING!$I:$I,$B22,PLANNING!$U:$U,Q$5) -> 0 | R22: =COUNTIFS(PLANNING!$I:$I,$B22,PLANNING!$U:$U,R$5) -> 0 | S22: =COUNTIFS(PLANNING!$I:$I,$B22,PLANNING!$U:$U,S$5) -> 8 | T22: =COUNTIFS(PLANNING!$I:$I,$B22,PLANNING!$U:$U,T$5) -> 21 | U22: =COUNTIFS(PLANNING!$I:$I,$B22,PLANNING!$U:$U,U$5) -> 11 | ... W22: =COUNTIFS(PLANNING!$I:$I,$B22,PLANNING!$U:$U,W$5) -> 5
A23: VENDREDI | B23: RABAT | C23: =COUNTIFS(PLANNING!$I:$I,$B23,PLANNING!$T:$T,C$5) -> 0 | D23: =COUNTIFS(PLANNING!$I:$I,$B23,PLANNING!$T:$T,D$5) -> 0 | E23: =COUNTIFS(PLANNING!$I:$I,$B23,PLANNING!$T:$T,E$5) -> 16 | F23: =COUNTIFS(PLANNING!$I:$I,$B23,PLANNING!$T:$T,F$5) -> 20 | G23: =COUNTIFS(PLANNING!$I:$I,$B23,PLANNING!$T:$T,G$5) -> 0 | H23: =COUNTIFS(PLANNING!$I:$I,$B23,PLANNING!$T:$T,H$5) -> 0 | I23: =COUNTIFS(PLANNING!$I:$I,$B23,PLANNING!$T:$T,I$5) -> 0 | J23: =COUNTIFS(PLANNING!$I:$I,$B23,PLANNING!$T:$T,J$5) -> 0 | L23: VENDREDI | M23: RABAT | N23: =COUNTIFS(PLANNING!$I:$I,$B23,PLANNING!$U:$U,N$5) -> 0 | O23: =COUNTIFS(PLANNING!$I:$I,$B23,PLANNING!$V:$V,O$5) -> 0 | P23: =COUNTIFS(PLANNING!$I:$I,$B23,PLANNING!$U:$U,P$5) -> 0 | Q23: =COUNTIFS(PLANNING!$I:$I,$B23,PLANNING!$U:$U,Q$5) -> 0 | R23: =COUNTIFS(PLANNING!$I:$I,$B23,PLANNING!$U:$U,R$5) -> 0 | S23: =COUNTIFS(PLANNING!$I:$I,$B23,PLANNING!$U:$U,S$5) -> 7 | T23: =COUNTIFS(PLANNING!$I:$I,$B23,PLANNING!$U:$U,T$5) -> 22 | U23: =COUNTIFS(PLANNING!$I:$I,$B23,PLANNING!$U:$U,U$5) -> 7 | V23: =COUNTIFS(PLANNING!$I:$I,$B23,PLANNING!$U:$U,V$5) -> 0 | W23: =COUNTIFS(PLANNING!$I:$I,$B23,PLANNING!$U:$U,W$5) -> 0
A24: VENDREDI | B24: SALE SALA AL JADIDA | C24: =COUNTIFS(PLANNING!$I:$I,LEFT($B$8,4),PLANNING!$T:$T,C$5)+COUNTIFS(PLANNING!$I:$I,RIGHT($B$8,14),PLANNING!$T:$T,C$5) -> 0 | D24: =COUNTIFS(PLANNING!$I:$I,LEFT($B$8,4),PLANNING!$T:$T,D$5)+COUNTIFS(PLANNING!$I:$I,RIGHT($B$8,14),PLANNING!$T:$T,D$5) -> 0 | E24: =COUNTIFS(PLANNING!$I:$I,LEFT($B$8,4),PLANNING!$T:$T,E$5)+COUNTIFS(PLANNING!$I:$I,RIGHT($B$8,14),PLANNING!$T:$T,E$5) -> 39 | F24: =COUNTIFS(PLANNING!$I:$I,LEFT($B$8,4),PLANNING!$T:$T,F$5)+COUNTIFS(PLANNING!$I:$I,RIGHT($B$8,14),PLANNING!$T:$T,F$5) -> 48 | G24: =COUNTIFS(PLANNING!$I:$I,LEFT($B$8,4),PLANNING!$T:$T,G$5)+COUNTIFS(PLANNING!$I:$I,RIGHT($B$8,14),PLANNING!$T:$T,G$5) -> 12 | H24: =COUNTIFS(PLANNING!$I:$I,LEFT($B$8,4),PLANNING!$T:$T,H$5)+COUNTIFS(PLANNING!$I:$I,RIGHT($B$8,14),PLANNING!$T:$T,H$5) -> 14 | I24: =COUNTIFS(PLANNING!$I:$I,LEFT($B$8,4),PLANNING!$T:$T,I$5)+COUNTIFS(PLANNING!$I:$I,RIGHT($B$8,14),PLANNING!$T:$T,I$5) -> 8 | J24: =COUNTIFS(PLANNING!$I:$I,LEFT($B$8,4),PLANNING!$T:$T,J$5)+COUNTIFS(PLANNING!$I:$I,RIGHT($B$8,14),PLANNING!$T:$T,J$5) -> 0 | L24: VENDREDI | M24: SALE SALA AL JADIDA | N24: =COUNTIFS(PLANNING!$I:$I,LEFT($B$24,4),PLANNING!$U:$U,N$5)+COUNTIFS(PLANNING!$I:$I,RIGHT($B$8,14),PLANNING!$U:$U,N$5) -> 0 | O24: =COUNTIFS(PLANNING!$I:$I,LEFT($B$8,4),PLANNING!$V:$V,O$5)+COUNTIFS(PLANNING!$I:$I,RIGHT($B$8,14),PLANNING!$V:$V,O$5) -> 0 | P24: =COUNTIFS(PLANNING!$I:$I,LEFT($B$8,4),PLANNING!$U:$U,P$5)+COUNTIFS(PLANNING!$I:$I,RIGHT($B$8,14),PLANNING!$U:$U,P$5) -> 0 | Q24: =COUNTIFS(PLANNING!$I:$I,LEFT($B$8,4),PLANNING!$U:$U,Q$5)+COUNTIFS(PLANNING!$I:$I,RIGHT($B$8,14),PLANNING!$U:$U,Q$5) -> 0 | R24: =COUNTIFS(PLANNING!$I:$I,LEFT($B$8,4),PLANNING!$U:$U,R$5)+COUNTIFS(PLANNING!$I:$I,RIGHT($B$8,14),PLANNING!$U:$U,R$5) -> 0 | S24: =COUNTIFS(PLANNING!$I:$I,LEFT($B$8,4),PLANNING!$U:$U,S$5)+COUNTIFS(PLANNING!$I:$I,RIGHT($B$8,14),PLANNING!$U:$U,S$5) -> 24 | T24: =COUNTIFS(PLANNING!$I:$I,LEFT($B$8,4),PLANNING!$U:$U,T$5)+COUNTIFS(PLANNING!$I:$I,RIGHT($B$8,14),PLANNING!$U:$U,T$5) -> 41 | U24: =COUNTIFS(PLANNING!$I:$I,LEFT($B$8,4),PLANNING!$U:$U,U$5)+COUNTIFS(PLANNING!$I:$I,RIGHT($B$8,14),PLANNING!$U:$U,U$5) -> 29 | V24: =COUNTIFS(PLANNING!$I:$I,LEFT($B$8,4),PLANNING!$U:$U,V$5)+COUNTIFS(PLANNING!$I:$I,RIGHT($B$8,14),PLANNING!$U:$U,V$5) -> 16 | W24: =COUNTIFS(PLANNING!$I:$I,LEFT($B$8,4),PLANNING!$U:$U,W$5)+COUNTIFS(PLANNING!$I:$I,RIGHT($B$8,14),PLANNING!$U:$U,W$5) -> 11
A25: VENDREDI | B25: TEMARA | C25: =COUNTIFS(PLANNING!$I:$I,$B25,PLANNING!$T:$T,C$5) -> 0 | D25: =COUNTIFS(PLANNING!$I:$I,$B25,PLANNING!$T:$T,D$5) -> 0 | E25: =COUNTIFS(PLANNING!$I:$I,$B25,PLANNING!$T:$T,E$5) -> 11 | F25: =COUNTIFS(PLANNING!$I:$I,$B25,PLANNING!$T:$T,F$5) -> 25 | G25: =COUNTIFS(PLANNING!$I:$I,$B25,PLANNING!$T:$T,G$5) -> 0 | H25: =COUNTIFS(PLANNING!$I:$I,$B25,PLANNING!$T:$T,H$5) -> 0 | I25: =COUNTIFS(PLANNING!$I:$I,$B25,PLANNING!$T:$T,I$5) -> 0 | J25: =COUNTIFS(PLANNING!$I:$I,$B25,PLANNING!$T:$T,J$5) -> 0 | L25: VENDREDI | M25: TEMARA | N25: =COUNTIFS(PLANNING!$I:$I,$B25,PLANNING!$U:$U,N$5) -> 0 | O25: =COUNTIFS(PLANNING!$I:$I,$B25,PLANNING!$V:$V,O$5) -> 0 | P25: =COUNTIFS(PLANNING!$I:$I,$B25,PLANNING!$U:$U,P$5) -> 0 | Q25: =COUNTIFS(PLANNING!$I:$I,$B25,PLANNING!$U:$U,Q$5) -> 0 | R25: =COUNTIFS(PLANNING!$I:$I,$B25,PLANNING!$U:$U,R$5) -> 0 | S25: =COUNTIFS(PLANNING!$I:$I,$B25,PLANNING!$U:$U,S$5) -> 6 | T25: =COUNTIFS(PLANNING!$I:$I,$B25,PLANNING!$U:$U,T$5) -> 18 | U25: =COUNTIFS(PLANNING!$I:$I,$B25,PLANNING!$U:$U,U$5) -> 12 | V25: =COUNTIFS(PLANNING!$I:$I,$B25,PLANNING!$U:$U,V$5) -> 0 | W25: =COUNTIFS(PLANNING!$I:$I,$B25,PLANNING!$U:$U,W$5) -> 0
A26: SAMEDI | B26: KENITRA | C26: =COUNTIFS(PLANNING!$I:$I,$B26,PLANNING!$V:$V,C$5) -> 0 | D26: =COUNTIFS(PLANNING!$I:$I,$B26,PLANNING!$V:$V,D$5) -> 0 | E26: =COUNTIFS(PLANNING!$I:$I,$B26,PLANNING!$V:$V,E$5) -> 20 | F26: =COUNTIFS(PLANNING!$I:$I,$B26,PLANNING!$V:$V,F$5) -> 0 | G26: =COUNTIFS(PLANNING!$I:$I,$B26,PLANNING!$V:$V,G$5) -> 0 | H26: =COUNTIFS(PLANNING!$I:$I,$B26,PLANNING!$V:$V,H$5) -> 5 | I26: =COUNTIFS(PLANNING!$I:$I,$B26,PLANNING!$V:$V,I$5) -> 0 | J26: =COUNTIFS(PLANNING!$I:$I,$B26,PLANNING!$V:$V,J$5) -> 0 | L26: SAMEDI | M26: KENITRA | N26: =COUNTIFS(PLANNING!$I:$I,$B26,PLANNING!$W:$W,N$5) -> 4 | O26: =COUNTIFS(PLANNING!$I:$I,$B26,PLANNING!$W:$W,O$5) -> 0 | P26: =COUNTIFS(PLANNING!$I:$I,$B26,PLANNING!$W:$W,P$5) -> 5 | Q26: =COUNTIFS(PLANNING!$I:$I,$B26,PLANNING!$W:$W,Q$5) -> 0 | R26: =COUNTIFS(PLANNING!$I:$I,$B26,PLANNING!$W:$W,R$5) -> 0 | S26: =COUNTIFS(PLANNING!$I:$I,$B26,PLANNING!$W:$W,S$5) -> 11 | T26: =COUNTIFS(PLANNING!$I:$I,$B26,PLANNING!$W:$W,T$5) -> 0 | U26: =COUNTIFS(PLANNING!$I:$I,$B26,PLANNING!$W:$W,U$5) -> 0 | ... W26: =COUNTIFS(PLANNING!$I:$I,$B26,PLANNING!$W:$W,W$5) -> 5
A27: SAMEDI | B27: RABAT | C27: =COUNTIFS(PLANNING!$I:$I,$B27,PLANNING!$V:$V,C$5) -> 0 | D27: =COUNTIFS(PLANNING!$I:$I,$B27,PLANNING!$V:$V,D$5) -> 0 | E27: =COUNTIFS(PLANNING!$I:$I,$B27,PLANNING!$V:$V,E$5) -> 15 | F27: =COUNTIFS(PLANNING!$I:$I,$B27,PLANNING!$V:$V,F$5) -> 0 | G27: =COUNTIFS(PLANNING!$I:$I,$B27,PLANNING!$V:$V,G$5) -> 0 | H27: =COUNTIFS(PLANNING!$I:$I,$B27,PLANNING!$V:$V,H$5) -> 0 | I27: =COUNTIFS(PLANNING!$I:$I,$B27,PLANNING!$V:$V,I$5) -> 0 | J27: =COUNTIFS(PLANNING!$I:$I,$B27,PLANNING!$V:$V,J$5) -> 0 | L27: SAMEDI | M27: RABAT | N27: =COUNTIFS(PLANNING!$I:$I,$B27,PLANNING!$W:$W,N$5) -> 2 | O27: =COUNTIFS(PLANNING!$I:$I,$B27,PLANNING!$W:$W,O$5) -> 0 | P27: =COUNTIFS(PLANNING!$I:$I,$B27,PLANNING!$W:$W,P$5) -> 6 | Q27: =COUNTIFS(PLANNING!$I:$I,$B27,PLANNING!$W:$W,Q$5) -> 0 | R27: =COUNTIFS(PLANNING!$I:$I,$B27,PLANNING!$W:$W,R$5) -> 0 | S27: =COUNTIFS(PLANNING!$I:$I,$B27,PLANNING!$W:$W,S$5) -> 7 | T27: =COUNTIFS(PLANNING!$I:$I,$B27,PLANNING!$W:$W,T$5) -> 0 | U27: =COUNTIFS(PLANNING!$I:$I,$B27,PLANNING!$W:$W,U$5) -> 0 | ... W27: =COUNTIFS(PLANNING!$I:$I,$B27,PLANNING!$W:$W,W$5) -> 0
A28: SAMEDI | B28: SALE SALA AL JADIDA | C28: =COUNTIFS(PLANNING!$I:$I,LEFT($B$8,4),PLANNING!$V:$V,C$5)+COUNTIFS(PLANNING!$I:$I,RIGHT($B$8,14),PLANNING!$V:$V,C$5) -> 0 | D28: =COUNTIFS(PLANNING!$I:$I,LEFT($B$8,4),PLANNING!$V:$V,D$5)+COUNTIFS(PLANNING!$I:$I,RIGHT($B$8,14),PLANNING!$V:$V,D$5) -> 0 | E28: =COUNTIFS(PLANNING!$I:$I,LEFT($B$8,4),PLANNING!$V:$V,E$5)+COUNTIFS(PLANNING!$I:$I,RIGHT($B$8,14),PLANNING!$V:$V,E$5) -> 42 | F28: =COUNTIFS(PLANNING!$I:$I,LEFT($B$8,4),PLANNING!$V:$V,F$5)+COUNTIFS(PLANNING!$I:$I,RIGHT($B$8,14),PLANNING!$V:$V,F$5) -> 17 | G28: =COUNTIFS(PLANNING!$I:$I,LEFT($B$8,4),PLANNING!$V:$V,G$5)+COUNTIFS(PLANNING!$I:$I,RIGHT($B$8,14),PLANNING!$V:$V,G$5) -> 0 | H28: =COUNTIFS(PLANNING!$I:$I,LEFT($B$8,4),PLANNING!$V:$V,H$5)+COUNTIFS(PLANNING!$I:$I,RIGHT($B$8,14),PLANNING!$V:$V,H$5) -> 5 | I28: =COUNTIFS(PLANNING!$I:$I,LEFT($B$8,4),PLANNING!$V:$V,I$5)+COUNTIFS(PLANNING!$I:$I,RIGHT($B$8,14),PLANNING!$V:$V,I$5) -> 0 | J28: =COUNTIFS(PLANNING!$I:$I,LEFT($B$8,4),PLANNING!$V:$V,J$5)+COUNTIFS(PLANNING!$I:$I,RIGHT($B$8,14),PLANNING!$V:$V,J$5) -> 0 | L28: SAMEDI | M28: SALE SALA AL JADIDA | N28: =COUNTIFS(PLANNING!$I:$I,LEFT($B$8,4),PLANNING!$W:$W,N$5)+COUNTIFS(PLANNING!$I:$I,RIGHT($B$8,14),PLANNING!$W:$W,N$5) -> 15 | O28: =COUNTIFS(PLANNING!$I:$I,LEFT($B$8,4),PLANNING!$W:$W,O$5)+COUNTIFS(PLANNING!$I:$I,RIGHT($B$8,14),PLANNING!$W:$W,O$5) -> 0 | P28: =COUNTIFS(PLANNING!$I:$I,LEFT($B$8,4),PLANNING!$W:$W,P$5)+COUNTIFS(PLANNING!$I:$I,RIGHT($B$8,14),PLANNING!$W:$W,P$5) -> 16 | Q28: =COUNTIFS(PLANNING!$I:$I,LEFT($B$8,4),PLANNING!$W:$W,Q$5)+COUNTIFS(PLANNING!$I:$I,RIGHT($B$8,14),PLANNING!$W:$W,Q$5) -> 0 | R28: =COUNTIFS(PLANNING!$I:$I,LEFT($B$8,4),PLANNING!$W:$W,R$5)+COUNTIFS(PLANNING!$I:$I,RIGHT($B$8,14),PLANNING!$W:$W,R$5) -> 0 | S28: =COUNTIFS(PLANNING!$I:$I,LEFT($B$8,4),PLANNING!$W:$W,S$5)+COUNTIFS(PLANNING!$I:$I,RIGHT($B$8,14),PLANNING!$W:$W,S$5) -> 10 | T28: =COUNTIFS(PLANNING!$I:$I,LEFT($B$8,4),PLANNING!$W:$W,T$5)+COUNTIFS(PLANNING!$I:$I,RIGHT($B$8,14),PLANNING!$W:$W,T$5) -> 10 | U28: =COUNTIFS(PLANNING!$I:$I,LEFT($B$8,4),PLANNING!$W:$W,U$5)+COUNTIFS(PLANNING!$I:$I,RIGHT($B$8,14),PLANNING!$W:$W,U$5) -> 8 | ... W28: =COUNTIFS(PLANNING!$I:$I,LEFT($B$8,4),PLANNING!$W:$W,W$5)+COUNTIFS(PLANNING!$I:$I,RIGHT($B$8,14),PLANNING!$W:$W,W$5) -> 5
A29: SAMEDI | B29: TEMARA | C29: =COUNTIFS(PLANNING!$I:$I,$B29,PLANNING!$V:$V,C$5) -> 0 | D29: =COUNTIFS(PLANNING!$I:$I,$B29,PLANNING!$V:$V,D$5) -> 0 | E29: =COUNTIFS(PLANNING!$I:$I,$B29,PLANNING!$V:$V,E$5) -> 19 | F29: =COUNTIFS(PLANNING!$I:$I,$B29,PLANNING!$V:$V,F$5) -> 5 | G29: =COUNTIFS(PLANNING!$I:$I,$B29,PLANNING!$V:$V,G$5) -> 0 | H29: =COUNTIFS(PLANNING!$I:$I,$B29,PLANNING!$V:$V,H$5) -> 0 | I29: =COUNTIFS(PLANNING!$I:$I,$B29,PLANNING!$V:$V,I$5) -> 0 | J29: =COUNTIFS(PLANNING!$I:$I,$B29,PLANNING!$V:$V,J$5) -> 0 | L29: SAMEDI | M29: TEMARA | N29: =COUNTIFS(PLANNING!$I:$I,$B29,PLANNING!$W:$W,N$5) -> 5 | O29: =COUNTIFS(PLANNING!$I:$I,$B29,PLANNING!$W:$W,O$5) -> 0 | P29: =COUNTIFS(PLANNING!$I:$I,$B29,PLANNING!$W:$W,P$5) -> 14 | Q29: =COUNTIFS(PLANNING!$I:$I,$B29,PLANNING!$W:$W,Q$5) -> 0 | R29: =COUNTIFS(PLANNING!$I:$I,$B29,PLANNING!$W:$W,R$5) -> 0 | S29: =COUNTIFS(PLANNING!$I:$I,$B29,PLANNING!$W:$W,S$5) -> 0 | T29: =COUNTIFS(PLANNING!$I:$I,$B29,PLANNING!$W:$W,T$5) -> 5 | U29: =COUNTIFS(PLANNING!$I:$I,$B29,PLANNING!$W:$W,U$5) -> 0 | ... W29: =COUNTIFS(PLANNING!$I:$I,$B29,PLANNING!$W:$W,W$5) -> 0
A30: DIMANCHE | B30: KENITRA | C30: =COUNTIFS(PLANNING!$I:$I,$B30,PLANNING!$X:$X,C$5) -> 0 | D30: =COUNTIFS(PLANNING!$I:$I,$B30,PLANNING!$X:$X,D$5) -> 0 | E30: =COUNTIFS(PLANNING!$I:$I,$B30,PLANNING!$X:$X,E$5) -> 0 | F30: =COUNTIFS(PLANNING!$I:$I,$B30,PLANNING!$X:$X,F$5) -> 0 | G30: =COUNTIFS(PLANNING!$I:$I,$B30,PLANNING!$X:$X,G$5) -> 0 | H30: =COUNTIFS(PLANNING!$I:$I,$B30,PLANNING!$X:$X,H$5) -> 0 | I30: =COUNTIFS(PLANNING!$I:$I,$B30,PLANNING!$X:$X,I$5) -> 0 | J30: =COUNTIFS(PLANNING!$I:$I,$B30,PLANNING!$X:$X,J$5) -> 0 | L30: DIMANCHE | M30: KENITRA | N30: =COUNTIFS(PLANNING!$I:$I,$B30,PLANNING!$Y:$Y,N$5) -> 0 | O30: =COUNTIFS(PLANNING!$I:$I,$B30,PLANNING!$Y:$Y,O$5) -> 0 | P30: =COUNTIFS(PLANNING!$I:$I,$B30,PLANNING!$Y:$Y,P$5) -> 0 | Q30: =COUNTIFS(PLANNING!$I:$I,$B30,PLANNING!$Y:$Y,Q$5) -> 0 | R30: =COUNTIFS(PLANNING!$I:$I,$B30,PLANNING!$Y:$Y,R$5) -> 0 | S30: =COUNTIFS(PLANNING!$I:$I,$B30,PLANNING!$Y:$Y,S$5) -> 0 | T30: =COUNTIFS(PLANNING!$I:$I,$B30,PLANNING!$Y:$Y,T$5) -> 0 | U30: =COUNTIFS(PLANNING!$I:$I,$B30,PLANNING!$Y:$Y,U$5) -> 0 | ... W30: =COUNTIFS(PLANNING!$I:$I,$B30,PLANNING!$Y:$Y,W$5) -> 0
A31: DIMANCHE | B31: RABAT | C31: =COUNTIFS(PLANNING!$I:$I,$B31,PLANNING!$X:$X,C$5) -> 0 | D31: =COUNTIFS(PLANNING!$I:$I,$B31,PLANNING!$X:$X,D$5) -> 0 | E31: =COUNTIFS(PLANNING!$I:$I,$B31,PLANNING!$X:$X,E$5) -> 0 | F31: =COUNTIFS(PLANNING!$I:$I,$B31,PLANNING!$X:$X,F$5) -> 0 | G31: =COUNTIFS(PLANNING!$I:$I,$B31,PLANNING!$X:$X,G$5) -> 0 | H31: =COUNTIFS(PLANNING!$I:$I,$B31,PLANNING!$X:$X,H$5) -> 0 | I31: =COUNTIFS(PLANNING!$I:$I,$B31,PLANNING!$X:$X,I$5) -> 0 | J31: =COUNTIFS(PLANNING!$I:$I,$B31,PLANNING!$X:$X,J$5) -> 0 | L31: DIMANCHE | M31: RABAT | N31: =COUNTIFS(PLANNING!$I:$I,$B31,PLANNING!$Y:$Y,N$5) -> 0 | O31: =COUNTIFS(PLANNING!$I:$I,$B31,PLANNING!$Y:$Y,O$5) -> 0 | P31: =COUNTIFS(PLANNING!$I:$I,$B31,PLANNING!$Y:$Y,P$5) -> 0 | Q31: =COUNTIFS(PLANNING!$I:$I,$B31,PLANNING!$Y:$Y,Q$5) -> 0 | R31: =COUNTIFS(PLANNING!$I:$I,$B31,PLANNING!$Y:$Y,R$5) -> 0 | S31: =COUNTIFS(PLANNING!$I:$I,$B31,PLANNING!$Y:$Y,S$5) -> 0 | T31: =COUNTIFS(PLANNING!$I:$I,$B31,PLANNING!$Y:$Y,T$5) -> 0 | U31: =COUNTIFS(PLANNING!$I:$I,$B31,PLANNING!$Y:$Y,U$5) -> 0 | ... W31: =COUNTIFS(PLANNING!$I:$I,$B31,PLANNING!$Y:$Y,W$5) -> 0
A32: DIMANCHE | B32: SALE SALA AL JADIDA | C32: =COUNTIFS(PLANNING!$I:$I,LEFT($B$8,4),PLANNING!$X:$X,C$5)+COUNTIFS(PLANNING!$I:$I,RIGHT($B$8,14),PLANNING!$X:$X,C$5) -> 0 | D32: =COUNTIFS(PLANNING!$I:$I,LEFT($B$8,4),PLANNING!$X:$X,D$5)+COUNTIFS(PLANNING!$I:$I,RIGHT($B$8,14),PLANNING!$X:$X,D$5) -> 0 | E32: =COUNTIFS(PLANNING!$I:$I,LEFT($B$8,4),PLANNING!$X:$X,E$5)+COUNTIFS(PLANNING!$I:$I,RIGHT($B$8,14),PLANNING!$X:$X,E$5) -> 0 | F32: =COUNTIFS(PLANNING!$I:$I,LEFT($B$8,4),PLANNING!$X:$X,F$5)+COUNTIFS(PLANNING!$I:$I,RIGHT($B$8,14),PLANNING!$X:$X,F$5) -> 0 | G32: =COUNTIFS(PLANNING!$I:$I,LEFT($B$8,4),PLANNING!$X:$X,G$5)+COUNTIFS(PLANNING!$I:$I,RIGHT($B$8,14),PLANNING!$X:$X,G$5) -> 0 | H32: =COUNTIFS(PLANNING!$I:$I,LEFT($B$8,4),PLANNING!$X:$X,H$5)+COUNTIFS(PLANNING!$I:$I,RIGHT($B$8,14),PLANNING!$X:$X,H$5) -> 0 | I32: =COUNTIFS(PLANNING!$I:$I,LEFT($B$8,4),PLANNING!$X:$X,I$5)+COUNTIFS(PLANNING!$I:$I,RIGHT($B$8,14),PLANNING!$X:$X,I$5) -> 0 | J32: =COUNTIFS(PLANNING!$I:$I,LEFT($B$8,4),PLANNING!$X:$X,J$5)+COUNTIFS(PLANNING!$I:$I,RIGHT($B$8,14),PLANNING!$X:$X,J$5) -> 0 | L32: DIMANCHE | M32: SALE SALA AL JADIDA | N32: =COUNTIFS(PLANNING!$I:$I,LEFT($B$8,4),PLANNING!$Y:$Y,N$5)+COUNTIFS(PLANNING!$I:$I,RIGHT($B$8,14),PLANNING!$Y:$Y,N$5) -> 0 | O32: =COUNTIFS(PLANNING!$I:$I,LEFT($B$8,4),PLANNING!$Y:$Y,O$5)+COUNTIFS(PLANNING!$I:$I,RIGHT($B$8,14),PLANNING!$Y:$Y,O$5) -> 0 | P32: =COUNTIFS(PLANNING!$I:$I,LEFT($B$8,4),PLANNING!$Y:$Y,P$5)+COUNTIFS(PLANNING!$I:$I,RIGHT($B$8,14),PLANNING!$Y:$Y,P$5) -> 0 | Q32: =COUNTIFS(PLANNING!$I:$I,LEFT($B$8,4),PLANNING!$Y:$Y,Q$5)+COUNTIFS(PLANNING!$I:$I,RIGHT($B$8,14),PLANNING!$Y:$Y,Q$5) -> 0 | R32: =COUNTIFS(PLANNING!$I:$I,LEFT($B$8,4),PLANNING!$Y:$Y,R$5)+COUNTIFS(PLANNING!$I:$I,RIGHT($B$8,14),PLANNING!$Y:$Y,R$5) -> 0 | S32: =COUNTIFS(PLANNING!$I:$I,LEFT($B$8,4),PLANNING!$Y:$Y,S$5)+COUNTIFS(PLANNING!$I:$I,RIGHT($B$8,14),PLANNING!$Y:$Y,S$5) -> 0 | T32: =COUNTIFS(PLANNING!$I:$I,LEFT($B$8,4),PLANNING!$Y:$Y,T$5)+COUNTIFS(PLANNING!$I:$I,RIGHT($B$8,14),PLANNING!$Y:$Y,T$5) -> 0 | U32: =COUNTIFS(PLANNING!$I:$I,LEFT($B$8,4),PLANNING!$Y:$Y,U$5)+COUNTIFS(PLANNING!$I:$I,RIGHT($B$8,14),PLANNING!$Y:$Y,U$5) -> 0 | ... W32: =COUNTIFS(PLANNING!$I:$I,LEFT($B$8,4),PLANNING!$Y:$Y,W$5)+COUNTIFS(PLANNING!$I:$I,RIGHT($B$8,14),PLANNING!$Y:$Y,W$5) -> 0
A33: DIMANCHE | B33: TEMARA | C33: =COUNTIFS(PLANNING!$I:$I,$B33,PLANNING!$X:$X,C$5) -> 0 | D33: =COUNTIFS(PLANNING!$I:$I,$B33,PLANNING!$X:$X,D$5) -> 0 | E33: =COUNTIFS(PLANNING!$I:$I,$B33,PLANNING!$X:$X,E$5) -> 0 | F33: =COUNTIFS(PLANNING!$I:$I,$B33,PLANNING!$X:$X,F$5) -> 0 | G33: =COUNTIFS(PLANNING!$I:$I,$B33,PLANNING!$X:$X,G$5) -> 0 | H33: =COUNTIFS(PLANNING!$I:$I,$B33,PLANNING!$X:$X,H$5) -> 0 | I33: =COUNTIFS(PLANNING!$I:$I,$B33,PLANNING!$X:$X,I$5) -> 0 | J33: =COUNTIFS(PLANNING!$I:$I,$B33,PLANNING!$X:$X,J$5) -> 0 | L33: DIMANCHE | M33: TEMARA | N33: =COUNTIFS(PLANNING!$I:$I,$B33,PLANNING!$Y:$Y,N$5) -> 0 | O33: =COUNTIFS(PLANNING!$I:$I,$B33,PLANNING!$Y:$Y,O$5) -> 0 | P33: =COUNTIFS(PLANNING!$I:$I,$B33,PLANNING!$Y:$Y,P$5) -> 0 | Q33: =COUNTIFS(PLANNING!$I:$I,$B33,PLANNING!$Y:$Y,Q$5) -> 0 | R33: =COUNTIFS(PLANNING!$I:$I,$B33,PLANNING!$Y:$Y,R$5) -> 0 | S33: =COUNTIFS(PLANNING!$I:$I,$B33,PLANNING!$Y:$Y,S$5) -> 0 | T33: =COUNTIFS(PLANNING!$I:$I,$B33,PLANNING!$Y:$Y,T$5) -> 0 | U33: =COUNTIFS(PLANNING!$I:$I,$B33,PLANNING!$Y:$Y,U$5) -> 0 | ... W33: =COUNTIFS(PLANNING!$I:$I,$B33,PLANNING!$Y:$Y,W$5) -> 0
